2017-11-17 18:45:21,866 - streamparse.stdout - INFO - Could not create tcount
2017-11-17 18:45:21,867 - streamparse.stdout - INFO - ERROR:  database "tcount" already exists

2017-11-17 18:45:21,867 - streamparse.stdout - INFO - None
2017-11-17 18:45:22,051 - streamparse.stdout - INFO - could not create table
2017-11-17 18:45:22,051 - streamparse.stdout - INFO - ERROR:  relation "tweetwordcount" already exists

2017-11-17 18:45:22,051 - streamparse.stdout - INFO - None
2017-11-17 18:45:22,052 - streamparse.stdout - INFO - ucount = 
2017-11-17 18:45:22,052 - streamparse.stdout - INFO - 1
2017-11-17 18:45:22,053 - streamparse.stdout - INFO - uword = 
2017-11-17 18:45:22,053 - streamparse.stdout - INFO - Grandpa
2017-11-17 18:45:22,059 - streamparse.storm.component - ERROR - Exception in WordCounter.run()
Traceback (most recent call last):
  File "/usr/lib/python2.7/site-packages/streamparse-2.1.4-py2.7.egg/streamparse/storm/component.py", line 489, in run
    self._run()
  File "/usr/lib/python2.7/site-packages/streamparse-2.1.4-py2.7.egg/streamparse/storm/bolt.py", line 219, in _run
    self.process(tup)
  File "bolts/wordcount.py", line 66, in process
    cur.execute("UPDATE tweetwordcount SET count=%s WHERE word = %s", (uCount, uWord))
InternalError: current transaction is aborted, commands ignored until end of transaction block

